<?xml version="1.0"?>
<robot xmlns:sensor="http://playerstage.sourceforge.net/gazebo/xmlschema/#sensor"
       xmlns:controller="http://playerstage.sourceforge.net/gazebo/xmlschema/#controller"
       xmlns:interface="http://playerstage.sourceforge.net/gazebo/xmlschema/#interface"
       xmlns:xacro="http://ros.org/wiki/xacro">

  <include filename="$(find bosch_arm_description)/urdf/base/base.gazebo.xacro" />
  <include filename="$(find bosch_arm_description)/urdf/base/base.transmission.xacro" />
  <include filename="$(find bosch_arm_description)/urdf/base/actuator.info.xacro" />

  <!-- DATA SOURCES -->
  <!-- all link geometry sizes are obtained from Function provided CAD model unless stated otherwise -->
  <!-- all simplified collision geometry are hand approximated from CAD model, sometimes from respective bounding boxes -->

  <property name="M_PI" value="3.1415926535897931" />
  <property name="base_mass" value="5.743031" />
  <property name="base_cm_x" value="-0.000694" />
  <property name="base_cm_y" value="-0.218533" />
  <property name="base_cm_z" value="-0.000038" />
  <property name="link1_mass" value="0.744800" />
  <property name="link1_cm_x" value="0" />
  <property name="link1_cm_y" value="0" />
  <property name="link1_cm_z" value="0" />
  <property name="link2_mass" value="0.104379" />
  <property name="link2_cm_x" value="0" />
  <property name="link2_cm_y" value="0.014484" />
  <property name="link2_cm_z" value="0" />
  <property name="link3_mass" value="0.091407" />
  <property name="link3_cm_x" value="0" />
  <property name="link3_cm_y" value="-0.003365" />
  <property name="link3_cm_z" value="0.293324" />
  <property name="link4_mass" value="0.129569" />
  <property name="link4_cm_x" value="0.006155" />
  <property name="link4_cm_y" value="0.156038" />
  <property name="link4_cm_z" value="0" />

  <property name="base_z" value="0.35" />
  <property name="link4_y" value="-0.04405" />
  <property name="link4_z" value="0.55145" />
  <property name="link5_x" value="0.01109" />
  <property name="link5_y" value="0.51477" />

      <property name="r1" value="0.062811565304088" />
    <property name="r2" value="0.12524850894632" />
    <property name="r3" value="15.9206349206349" />
    <property name="r4" value="7.98412698412698" />


  <xacro:macro name="bosch_arm" params="name">

    <link name="${name}_footprint">
      <inertial>
        <mass value="0.001" />
        <origin xyz="0 0 0" />
        <inertia ixx="0.01" ixy="0.0" ixz="0.0"
                 iyy="0.01" iyz="0.0" izz="0.01" />
      </inertial>
      <visual>
        <origin xyz="0 0 0" rpy="0 0 0" />
        <geometry>
          <box size="0.01 0.01 0.01" />
        </geometry>
        
        <material name="Black" />
      </visual>
      <collision>
        <origin xyz="0 0 ${base_z}" rpy="0 0 0" />
        <geometry>
          <box size="0.001 0.001 0.001" />
        </geometry>
      </collision>
    </link>

    <link name="${name}_link">
      <inertial>
        <mass value="${base_mass}" />
        <origin xyz="${base_cm_x} ${base_cm_y} ${base_cm_z}" />
        <inertia ixx="0.148153" ixy="-0.000987" ixz="0.000001"
                 iyy="0.161046" iyz="-0.000028" izz="0.043711" />
      </inertial>

      <visual>
        <origin xyz="0 0 0" rpy="0 0 0" />
        <geometry>
          <mesh filename="package://bosch_arm_description/meshes/base-simple.stl" />
        </geometry>
        
        <material name="White" />
      </visual>

      <collision>
        <origin xyz="0 0 0" rpy="0 0 0" />
        <geometry>
          <mesh filename="package://bosch_arm_description/meshes/base-simple.stl" />
        </geometry>
      </collision>
    </link>

    <link name="${name}_link1">

      <inertial>
        <mass value="${link1_mass}" />
        <origin xyz="${link1_cm_x} ${link1_cm_y} ${link1_cm_z}" />
        <inertia ixx="0.007733" ixy="0" ixz="0"
                 iyy="0.010218" iyz="0" izz="0.002684" />
      </inertial>

      <visual>
        <origin xyz="0 0 0" rpy="0 0 0" />
        <geometry>
          <mesh filename="package://bosch_arm_description/meshes/joint1-simple.stl" />
        </geometry>
        
        <material name="White" />
      </visual>

      <collision>
        <origin xyz="0 0 0" rpy="0 0 0" />
        <geometry>
          <mesh filename="package://bosch_arm_description/meshes/joint1-simple.stl" />
        </geometry>
      </collision>
    </link>

    <link name="${name}_link2">

      <inertial>
        <mass value="${link2_mass}" />
        <origin xyz="${link2_cm_x} ${link2_cm_y} ${link2_cm_z}" />
        <inertia ixx="0.000205" ixy="0" ixz="0"
                 iyy="0.000191" iyz="0" izz="0.000048" />
      </inertial>

      <visual>
        <origin xyz="0 0 0" rpy="0 0 0" />
        <geometry>
          <mesh filename="package://bosch_arm_description/meshes/joint2-simple.stl" />
        </geometry>
        
        <material name="White" />
      </visual>

      <collision>
        <origin xyz="0 0 0" rpy="0 0 0" />
        <geometry>
          <mesh filename="package://bosch_arm_description/meshes/joint2-simple.stl" />
        </geometry>
      </collision>
    </link>


    <link name="${name}_link3">
      <inertial>
        <mass value="${link3_mass}" />
        <origin xyz="${link3_cm_x} ${link3_cm_y} ${link3_cm_z}" />
        <inertia ixx="0.002540" ixy="0" ixz="0"
                 iyy="0.002530" iyz="-0.000077" izz="0.000018" />
      </inertial>

      <visual>
        <origin xyz="0 0 0" rpy="0 0 0" />
        <geometry>
          <mesh filename="package://bosch_arm_description/meshes/joint3-simple.stl" />
        </geometry>
        <material name="White" />
      </visual>

      <collision>
        <origin xyz="0 0 0" rpy="0 0 0" />
        <geometry>
          <mesh filename="package://bosch_arm_description/meshes/joint3-simple.stl" />
        </geometry>
      </collision>
    </link>


    <link name="${name}_link4">
      <inertial>
        <mass value="${link4_mass}" />
        <origin xyz="${link4_cm_x} ${link4_cm_y} ${link4_cm_z}" />
        <inertia ixx="0.003878" ixy="0" ixz="0"
                 iyy="0.000045" iyz="0" izz="0.003917" />
      </inertial>

      <visual>
        <origin xyz="0 0 0" rpy="0 0 0" />
        <geometry>
          <mesh filename="package://bosch_arm_description/meshes/joint4-simple.stl" />
        </geometry>
        
        <material name="White" />
      </visual>

      <collision>
        <origin xyz="0 0 0" rpy="0 0 0" />
        <geometry>
          <mesh filename="package://bosch_arm_description/meshes/joint4-simple.stl" />
        </geometry>
      </collision>
    </link>

    <link name="${name}_link5">
      <inertial>
        <mass value="0.001" />
        <origin xyz="0 0 0" />
        <inertia ixx="0.003878" ixy="0" ixz="0"
                 iyy="0.000045" iyz="0" izz="0.003917" />
      </inertial>

      <visual>
        <origin xyz="0 0 0" rpy="0 0 0" />
        <geometry>
          <box size="0.001 0.001 0.001" />
        </geometry>
        <material name="White" />
      </visual>

      <collision>
        <origin xyz="0 0 0" rpy="0 0 0" />
        <geometry>
          <box size="0.001 0.001 0.001" />
        </geometry>
      </collision>
    </link>
    
    
    <link name="${name}_link6">
      <inertial>
        <mass value="0.001" />
        <origin xyz="0 0 0" />
        <inertia ixx="0.003878" ixy="0" ixz="0"
                 iyy="0.000045" iyz="0" izz="0.003917" />
      </inertial>

      <visual>
        <origin xyz="0 0 0" rpy="0 0 0" />
        <geometry>
          <box size="0.001 0.001 0.001" />
        </geometry>
        <material name="White" />
      </visual>

      <collision>
        <origin xyz="0 0 0" rpy="0 0 0" />
        <geometry>
          <box size="0.001 0.001 0.001" />
        </geometry>
      </collision>
    </link>
    
    
    
    
    
    <joint name="${name}_footprint_joint" type="fixed">
      <origin xyz="0 0 ${base_z}" rpy="${M_PI/2} 0 0" />
      <child link="${name}_link" />
      <parent link="${name}_footprint"/>
    </joint>

    <joint name="${name}_joint1" type="revolute">
      <axis xyz="0 0 1" />
      <origin xyz="0 0 0" rpy="0 0 0" />
      <limit effort="100" velocity="100" lower="${-M_PI/2}" upper="${M_PI/2}" /> <!-- alpha tested velocity and effort limits -->
      <safety_controller  k_velocity="10" />
      <!--calibration rising="${ref_position}" /-->
      <dynamics damping="0.0" friction="0.0" />
      <parent link="${name}_link"/>
      <child link="${name}_link1" />
    </joint>

    <joint name="${name}_joint2" type="revolute">
      <axis xyz="0 0 1" />
      <origin xyz="0 0 0" rpy=" 0 ${M_PI/2} 0" />
      <limit effort="100" velocity="100" lower="${-M_PI/2}" upper="${M_PI/2}"/> <!-- alpha tested velocity and effort limits -->
      <safety_controller  k_velocity="10" />
      <dynamics damping="0.0" friction="0.0" />
      <parent link="${name}_link1"/>
      <child link="${name}_link2" />
    </joint>

    <joint name="${name}_joint3" type="revolute">
      <axis xyz="0 0 1" />
      <origin xyz=" 0 0 0" rpy="${-M_PI/2} 0 0" />
      <limit effort="100" velocity="100" lower="${-M_PI/2}" upper="${M_PI/2}" /> <!-- alpha tested velocity and effort limits -->
      <safety_controller  k_velocity="10" />
      <dynamics damping="0.0" friction="0.0" />
      <parent link="${name}_link2"/>
      <child link="${name}_link3" />
    </joint>

    <joint name="${name}_joint4" type="continuous">
      <axis xyz="0 0 1" />
      <origin xyz="0 ${link4_y} ${link4_z}" rpy="0 ${M_PI/2} ${M_PI}" />
      <limit effort="100" velocity="100"/>
      <safety_controller  k_velocity="10" />
      <dynamics damping="0.0" friction="0.0" />
      <parent link="${name}_link3"/>
      <child link="${name}_link4" />
    </joint>

    <!--joint name="${name}_joint5" type="fixed">
      <axis xyz="0 0 1" />
      <origin xyz="${link5_x} ${link5_y} 0" rpy="0 0 0" />
      <limit effort="100" velocity="100"/>
      <safety_controller  k_velocity="10" />
      <dynamics damping="0.0" friction="0.0" />
      <parent link="${name}_link4"/>
      <child link="${name}_link5" />
    </joint-->
    
    <!--joint name="${name}_joint6" type="fixed">
      <axis xyz="0 0 1" />
      <origin xyz="0 0 0" rpy="0 0 0" />
      <limit effort="100" velocity="100"/>
      <safety_controller  k_velocity="10" />
      <dynamics damping="0.0" friction="0.0" />
      <parent link="${name}_link5"/>
      <child link="${name}_link6" />
    </joint-->
    
    <!-- gazebo extensions -->
    <xacro:bosch_arm_gazebo name="${name}" />
    
    <xacro:bosch_arm_joint_transmission name="${name}" suffix="1"/>
    <xacro:bosch_arm_joint_transmission name="${name}" suffix="2"/>
    <xacro:bosch_arm_joint_transmission name="${name}" suffix="3"/>
    <xacro:bosch_arm_joint_transmission name="${name}" suffix="4"/>
    
    <xacro:actuator_macro name="actuator1" cmd_addr="1" encoder_addr="1"/>
    <xacro:actuator_macro name="actuator2" cmd_addr="2" encoder_addr="2"/>
    <xacro:actuator_macro name="actuator3" cmd_addr="3" encoder_addr="3"/>
    <xacro:actuator_macro name="actuator4" cmd_addr="4" encoder_addr="4"/>


    <joint_to_motor_transmission>
      ${r3}, 0.0, 0.0, 0.0,
       ${r4},  ${r4}, 0.0, 0.0,
       ${r4},  ${r4},  ${r4}, 0.0,
      0.0, 0.0, 0.0,  ${r4}
    </joint_to_motor_transmission>

    <motor_to_joint_transmission>
      ${r1}, 0.0, 0.0, 0.0,
      -${r1},  ${r2}, 0.0, 0.0,
      0.0, -${r2},  ${r2}, 0.0,
      0.0, 0.0, 0.0,  ${r2}
    </motor_to_joint_transmission>
  </xacro:macro>


</robot>
